Workbook

Sheet Data Mentah
A1: DATA MENTAH — PENGGUNAAN OBAT MINGGUAN (SUMBER ASLI)
A2: Sumber: Data_Obat_Keluar_2023_2024_Gabungan.xlsx, sheet "Data Gabungan" (diunggah pengguna, tidak diubah nilainya). Baris 26/12/2022 adalah nilai awal (L0) untuk perhitungan DES; T0 = 0 untuk seluruh obat.
A4: No. | B4: Minggu | C4: Afolat | D4: Asam Mefenamat | E4: Amoxicillin | F4: Naturoksi | G4: Gentamicin Injeksi | H4: Tramadol Injeksi | I4: Nazovel Suppositoria | J4: Ceftriaxone | K4: Ringer Lactat | L4: Aquabidest | M4: Tranexamat Acid Injeksi | N4: Ondansetron Injeksi | O4: Sanmol Syrup | P4: Natavit | Q4: Epexol Syrup | R4: Apialys Syrup
A5: 0 | B5: 26/12/2022 | C5: 11 | D5: 25 | E5: 15 | F5: 28 | G5: 7 | H5: 23 | I5: 26 | J5: 11 | K5: 25 | L5: 15 | M5: 28 | N5: 7 | O5: 23 | P5: 26 | Q5: 13 | R5: 21
A6: 1 | B6: 02/01/2023 | C6: 70 | D6: 54 | E6: 69 | F6: 80 | G6: 37 | H6: 71 | I6: 60 | J6: 70 | K6: 54 | L6: 69 | M6: 80 | N6: 37 | O6: 71 | P6: 60 | Q6: 71 | R6: 74
A7: 2 | B7: 09/01/2023 | C7: 90 | D7: 80 | E7: 75 | F7: 104 | G7: 63 | H7: 76 | I7: 78 | J7: 90 | K7: 80 | L7: 75 | M7: 104 | N7: 63 | O7: 76 | P7: 78 | Q7: 88 | R7: 88
A8: 3 | B8: 16/01/2023 | C8: 101 | D8: 89 | E8: 95 | F8: 106 | G8: 78 | H8: 83 | I8: 91 | J8: 101 | K8: 89 | L8: 95 | M8: 106 | N8: 78 | O8: 83 | P8: 91 | Q8: 94 | R8: 103
A9: 4 | B9: 23/01/2023 | C9: 124 | D9: 114 | E9: 121 | F9: 127 | G9: 109 | H9: 114 | I9: 112 | J9: 124 | K9: 114 | L9: 121 | M9: 127 | N9: 109 | O9: 114 | P9: 112 | Q9: 125 | R9: 130
A10: 5 | B10: 30/01/2023 | C10: 128 | D10: 123 | E10: 116 | F10: 127 | G10: 133 | H10: 123 | I10: 121 | J10: 128 | K10: 123 | L10: 116 | M10: 127 | N10: 133 | O10: 123 | P10: 121 | Q10: 125 | R10: 118
A11: 6 | B11: 06/02/2023 | C11: 130 | D11: 129 | E11: 120 | F11: 121 | G11: 131 | H11: 128 | I11: 121 | J11: 130 | K11: 129 | L11: 120 | M11: 121 | N11: 131 | O11: 128 | P11: 121 | Q11: 125 | R11: 117
A12: 7 | B12: 13/02/2023 | C12: 125 | D12: 118 | E12: 109 | F12: 118 | G12: 130 | H12: 123 | I12: 122 | J12: 125 | K12: 118 | L12: 109 | M12: 118 | N12: 130 | O12: 123 | P12: 122 | Q12: 119 | R12: 113
A13: 8 | B13: 20/02/2023 | C13: 131 | D13: 117 | E13: 105 | F13: 114 | G13: 127 | H13: 120 | I13: 122 | J13: 131 | K13: 117 | L13: 105 | M13: 114 | N13: 127 | O13: 120 | P13: 122 | Q13: 118 | R13: 114
A14: 9 | B14: 27/02/2023 | C14: 121 | D14: 116 | E14: 104 | F14: 111 | G14: 122 | H14: 106 | I14: 123 | J14: 121 | K14: 116 | L14: 104 | M14: 111 | N14: 122 | O14: 106 | P14: 123 | Q14: 112 | R14: 120
A15: 10 | B15: 06/03/2023 | C15: 110 | D15: 108 | E15: 115 | F15: 101 | G15: 121 | H15: 104 | I15: 121 | J15: 110 | K15: 108 | L15: 115 | M15: 101 | N15: 121 | O15: 104 | P15: 121 | Q15: 108 | R15: 129
A16: 11 | B16: 13/03/2023 | C16: 107 | D16: 113 | E16: 126 | F16: 99 | G16: 127 | H16: 112 | I16: 116 | J16: 107 | K16: 113 | L16: 126 | M16: 99 | N16: 127 | O16: 112 | P16: 116 | Q16: 112 | R16: 122
... A110: 105 | B110: 30/12/2024 | C110: 109 | D110: 106 | E110: 100 | F110: 93 | G110: 91 | H110: 93 | I110: 114 | J110: 109 | K110: 106 | L110: 100 | M110: 93 | N110: 91 | O110: 93 | P110: 114 | Q110: 113 | R110: 111

Sheet Tabel 4.1 Statistik Deskriptif
A1: TABEL 4.1 — STATISTIK DESKRIPTIF PENGGUNAAN MINGGUAN 16 OBAT (2023–2024)
A2: Seluruh nilai dihitung otomatis (rumus AVERAGE/MIN/MAX/STDEV) dari sheet "Data Mentah", periode 1–105 (tidak termasuk baris L0/minggu 26/12/2022).
A4: No. | B4: Nama Obat | C4: n | D4: Min | E4: Maks | F4: Rata-rata | G4: Std. Dev. | H4: Keterangan
A5: 1 | B5: Afolat | C5: =COUNT('Data Mentah'!C6:C110) -> 105 | D5: =MIN('Data Mentah'!C6:C110) -> 70 | E5: =MAX('Data Mentah'!C6:C110) -> 135 | F5: =ROUND(AVERAGE('Data Mentah'!C6:C110),2) -> 116.74 | G5: =ROUND(STDEV('Data Mentah'!C6:C110),2) -> 10.75 | H5: Data unik
A6: 2 | B6: Asam Mefenamat | C6: =COUNT('Data Mentah'!D6:D110) -> 105 | D6: =MIN('Data Mentah'!D6:D110) -> 54 | E6: =MAX('Data Mentah'!D6:D110) -> 141 | F6: =ROUND(AVERAGE('Data Mentah'!D6:D110),2) -> 116.42 | G6: =ROUND(STDEV('Data Mentah'!D6:D110),2) -> 12.3 | H6: Data unik
A7: 3 | B7: Amoxicillin | C7: =COUNT('Data Mentah'!E6:E110) -> 105 | D7: =MIN('Data Mentah'!E6:E110) -> 69 | E7: =MAX('Data Mentah'!E6:E110) -> 139 | F7: =ROUND(AVERAGE('Data Mentah'!E6:E110),2) -> 116.5 | G7: =ROUND(STDEV('Data Mentah'!E6:E110),2) -> 11.59 | H7: Data unik
A8: 4 | B8: Naturoksi | C8: =COUNT('Data Mentah'!F6:F110) -> 105 | D8: =MIN('Data Mentah'!F6:F110) -> 80 | E8: =MAX('Data Mentah'!F6:F110) -> 142 | F8: =ROUND(AVERAGE('Data Mentah'!F6:F110),2) -> 117.28 | G8: =ROUND(STDEV('Data Mentah'!F6:F110),2) -> 12.06 | H8: Data unik
A9: 5 | B9: Gentamicin Injeksi | C9: =COUNT('Data Mentah'!G6:G110) -> 105 | D9: =MIN('Data Mentah'!G6:G110) -> 37 | E9: =MAX('Data Mentah'!G6:G110) -> 143 | F9: =ROUND(AVERAGE('Data Mentah'!G6:G110),2) -> 119.21 | G9: =ROUND(STDEV('Data Mentah'!G6:G110),2) -> 14.45 | H9: Data unik
A10: 6 | B10: Tramadol Injeksi | C10: =COUNT('Data Mentah'!H6:H110) -> 105 | D10: =MIN('Data Mentah'!H6:H110) -> 71 | E10: =MAX('Data Mentah'!H6:H110) -> 152 | F10: =ROUND(AVERAGE('Data Mentah'!H6:H110),2) -> 117.43 | G10: =ROUND(STDEV('Data Mentah'!H6:H110),2) -> 13.79 | H10: Data unik
A11: 7 | B11: Nazovel Suppositoria | C11: =COUNT('Data Mentah'!I6:I110) -> 105 | D11: =MIN('Data Mentah'!I6:I110) -> 60 | E11: =MAX('Data Mentah'!I6:I110) -> 138 | F11: =ROUND(AVERAGE('Data Mentah'!I6:I110),2) -> 118.93 | G11: =ROUND(STDEV('Data Mentah'!I6:I110),2) -> 11.16 | H11: Data unik
A12: 8 | B12: Ceftriaxone | C12: =COUNT('Data Mentah'!J6:J110) -> 105 | D12: =MIN('Data Mentah'!J6:J110) -> 70 | E12: =MAX('Data Mentah'!J6:J110) -> 135 | F12: =ROUND(AVERAGE('Data Mentah'!J6:J110),2) -> 116.74 | G12: =ROUND(STDEV('Data Mentah'!J6:J110),2) -> 10.75 | H12: Data identik dengan Afolat
A13: 9 | B13: Ringer Lactat | C13: =COUNT('Data Mentah'!K6:K110) -> 105 | D13: =MIN('Data Mentah'!K6:K110) -> 54 | E13: =MAX('Data Mentah'!K6:K110) -> 141 | F13: =ROUND(AVERAGE('Data Mentah'!K6:K110),2) -> 116.42 | G13: =ROUND(STDEV('Data Mentah'!K6:K110),2) -> 12.3 | H13: Data identik dengan Asam Mefenamat
A14: 10 | B14: Aquabidest | C14: =COUNT('Data Mentah'!L6:L110) -> 105 | D14: =MIN('Data Mentah'!L6:L110) -> 69 | E14: =MAX('Data Mentah'!L6:L110) -> 139 | F14: =ROUND(AVERAGE('Data Mentah'!L6:L110),2) -> 116.5 | G14: =ROUND(STDEV('Data Mentah'!L6:L110),2) -> 11.59 | H14: Data identik dengan Amoxicillin
A15: 11 | B15: Tranexamat Acid Injeksi | C15: =COUNT('Data Mentah'!M6:M110) -> 105 | D15: =MIN('Data Mentah'!M6:M110) -> 80 | E15: =MAX('Data Mentah'!M6:M110) -> 142 | F15: =ROUND(AVERAGE('Data Mentah'!M6:M110),2) -> 117.28 | G15: =ROUND(STDEV('Data Mentah'!M6:M110),2) -> 12.06 | H15: Data identik dengan Naturoksi
A16: 12 | B16: Ondansetron Injeksi | C16: =COUNT('Data Mentah'!N6:N110) -> 105 | D16: =MIN('Data Mentah'!N6:N110) -> 37 | E16: =MAX('Data Mentah'!N6:N110) -> 143 | F16: =ROUND(AVERAGE('Data Mentah'!N6:N110),2) -> 119.21 | G16: =ROUND(STDEV('Data Mentah'!N6:N110),2) -> 14.45 | H16: Data identik dengan Gentamicin Injeksi
A17: 13 | B17: Sanmol Syrup | C17: =COUNT('Data Mentah'!O6:O110) -> 105 | D17: =MIN('Data Mentah'!O6:O110) -> 71 | E17: =MAX('Data Mentah'!O6:O110) -> 152 | F17: =ROUND(AVERAGE('Data Mentah'!O6:O110),2) -> 117.43 | G17: =ROUND(STDEV('Data Mentah'!O6:O110),2) -> 13.79 | H17: Data identik dengan Tramadol Injeksi
A18: 14 | B18: Natavit | C18: =COUNT('Data Mentah'!P6:P110) -> 105 | D18: =MIN('Data Mentah'!P6:P110) -> 60 | E18: =MAX('Data Mentah'!P6:P110) -> 138 | F18: =ROUND(AVERAGE('Data Mentah'!P6:P110),2) -> 118.93 | G18: =ROUND(STDEV('Data Mentah'!P6:P110),2) -> 11.16 | H18: Data identik dengan Nazovel Suppositoria
A19: 15 | B19: Epexol Syrup | C19: =COUNT('Data Mentah'!Q6:Q110) -> 105 | D19: =MIN('Data Mentah'!Q6:Q110) -> 71 | E19: =MAX('Data Mentah'!Q6:Q110) -> 147 | F19: =ROUND(AVERAGE('Data Mentah'!Q6:Q110),2) -> 122 | G19: =ROUND(STDEV('Data Mentah'!Q6:Q110),2) -> 10.62 | H19: Data unik
A20: 16 | B20: Apialys Syrup | C20: =COUNT('Data Mentah'!R6:R110) -> 105 | D20: =MIN('Data Mentah'!R6:R110) -> 74 | E20: =MAX('Data Mentah'!R6:R110) -> 140 | F20: =ROUND(AVERAGE('Data Mentah'!R6:R110),2) -> 118.36 | G20: =ROUND(STDEV('Data Mentah'!R6:R110),2) -> 9.68 | H20: Data unik

Sheet Tabel 4.2 Data Identik
A1: TABEL 4.2 — VERIFIKASI PASANGAN OBAT DENGAN DATA MINGGUAN YANG IDENTIK
A2: Kolom "Jumlah Selisih" dihitung dengan SUMPRODUCT membandingkan seluruh 105 nilai kedua obat; 0 berarti seluruh nilai identik.
A4: No. | B4: Obat dengan Data Identik | C4: Sama dengan Data Obat | D4: Jumlah Selisih (105 minggu) | E4: Status
A5: 1 | B5: Ceftriaxone | C5: Afolat | D5: =SUMPRODUCT(--('Data Mentah'!J6:J110<>'Data Mentah'!C6:C110)) -> 0 | E5: =IF(D5=0,"Identik","Berbeda") -> Identik
A6: 2 | B6: Ringer Lactat | C6: Asam Mefenamat | D6: =SUMPRODUCT(--('Data Mentah'!K6:K110<>'Data Mentah'!D6:D110)) -> 0 | E6: =IF(D6=0,"Identik","Berbeda") -> Identik
A7: 3 | B7: Aquabidest | C7: Amoxicillin | D7: =SUMPRODUCT(--('Data Mentah'!L6:L110<>'Data Mentah'!E6:E110)) -> 0 | E7: =IF(D7=0,"Identik","Berbeda") -> Identik
A8: 4 | B8: Tranexamat Acid Injeksi | C8: Naturoksi | D8: =SUMPRODUCT(--('Data Mentah'!M6:M110<>'Data Mentah'!F6:F110)) -> 0 | E8: =IF(D8=0,"Identik","Berbeda") -> Identik
A9: 5 | B9: Ondansetron Injeksi | C9: Gentamicin Injeksi | D9: =SUMPRODUCT(--('Data Mentah'!N6:N110<>'Data Mentah'!G6:G110)) -> 0 | E9: =IF(D9=0,"Identik","Berbeda") -> Identik
A10: 6 | B10: Sanmol Syrup | C10: Tramadol Injeksi | D10: =SUMPRODUCT(--('Data Mentah'!O6:O110<>'Data Mentah'!H6:H110)) -> 0 | E10: =IF(D10=0,"Identik","Berbeda") -> Identik
A11: 7 | B11: Natavit | C11: Nazovel Suppositoria | D11: =SUMPRODUCT(--('Data Mentah'!P6:P110<>'Data Mentah'!I6:I110)) -> 0 | E11: =IF(D11=0,"Identik","Berbeda") -> Identik

Sheet Tabel 4.3 Pembagian Data
A1: TABEL 4.3 — HASIL PEMBAGIAN DATA LATIH DAN DATA UJI
A3: Kelompok Data | B3: Proporsi | C3: Periode ke- | D3: Rentang Tanggal | E3: Jumlah Minggu
A4: Data Latih (Training) | B4: 80% | C4: 1 - 84 | D4: =CONCATENATE('Data Mentah'!B6," - ",'Data Mentah'!B89) -> 02/01/2023 - 05/08/2024 | E4: =1+84-1-0 -> 84
A5: Data Uji (Testing) | B5: 20% | C5: 85 - 105 | D5: =CONCATENATE('Data Mentah'!B90," - ",'Data Mentah'!B110) -> 12/08/2024 - 30/12/2024 | E5: =105-84 -> 21
A6: Total | E6: =E4+E5 -> 105

Sheet DES_Afolat
A1: PERHITUNGAN DOUBLE EXPONENTIAL SMOOTHING — AFOLAT
A2: Rumus hidup: Level_t = α·Aktual_t + (1-α)·(Level_(t-1)+Tren_(t-1)); Tren_t = β·(Level_t-Level_(t-1)) + (1-β)·Tren_(t-1); Ramalan_t = Level_(t-1)+Tren_(t-1). Ubah α/β di bawah untuk menguji kombinasi lain — seluruh tabel & ringkasan terhitung ulang otomatis.
A4: Nama Obat: | B4: Afolat | D4: Alpha (α): | E4: 0.9 | G4: Beta (β): | H4: 0.1
A5: L0 (Level Awal): | B5: ='Data Mentah'!C5 -> 11 | D5: T0 (Tren Awal): | E5: 0
A7: Periode | B7: Minggu | C7: Aktual | D7: Level | E7: Tren | F7: Ramalan | G7: Error | H7: |Error| | I7: Error² | J7: APE (%)
A8: 0 | B8: ='Data Mentah'!B5 -> 26/12/2022 | C8: ='Data Mentah'!C5 -> 11 | D8: =$B$5 -> 11 | E8: =$E$5 -> 0
A9: 1 | B9: ='Data Mentah'!B6 -> 02/01/2023 | C9: ='Data Mentah'!C6 -> 70 | D9: =$E$4*C9+(1-$E$4)*(D8+E8) -> 64.1 | E9: =$H$4*(D9-D8)+(1-$H$4)*E8 -> 5.31 | F9: =D8+E8 -> 11 | G9: =C9-F9 -> 59 | H9: =ABS(G9) -> 59 | I9: =G9^2 -> 3481 | J9: =ABS(G9/C9)*100 -> 84.285714
A10: 2 | B10: ='Data Mentah'!B7 -> 09/01/2023 | C10: ='Data Mentah'!C7 -> 90 | D10: =$E$4*C10+(1-$E$4)*(D9+E9) -> 87.941 | E10: =$H$4*(D10-D9)+(1-$H$4)*E9 -> 7.1631 | F10: =D9+E9 -> 69.41 | G10: =C10-F10 -> 20.59 | H10: =ABS(G10) -> 20.59 | I10: =G10^2 -> 423.9481 | J10: =ABS(G10/C10)*100 -> 22.877778
A11: 3 | B11: ='Data Mentah'!B8 -> 16/01/2023 | C11: ='Data Mentah'!C8 -> 101 | D11: =$E$4*C11+(1-$E$4)*(D10+E10) -> 100.41041 | E11: =$H$4*(D11-D10)+(1-$H$4)*E10 -> 7.693731 | F11: =D10+E10 -> 95.1041 | G11: =C11-F11 -> 5.8959 | H11: =ABS(G11) -> 5.8959 | I11: =G11^2 -> 34.761637 | J11: =ABS(G11/C11)*100 -> 5.8375248
A12: 4 | B12: ='Data Mentah'!B9 -> 23/01/2023 | C12: ='Data Mentah'!C9 -> 124 | D12: =$E$4*C12+(1-$E$4)*(D11+E11) -> 122.41041 | E12: =$H$4*(D12-D11)+(1-$H$4)*E11 -> 9.1243583 | F12: =D11+E11 -> 108.10414 | G12: =C12-F12 -> 15.895859 | H12: =ABS(G12) -> 15.895859 | I12: =G12^2 -> 252.67833 | J12: =ABS(G12/C12)*100 -> 12.819241
A13: 5 | B13: ='Data Mentah'!B10 -> 30/01/2023 | C13: ='Data Mentah'!C10 -> 128 | D13: =$E$4*C13+(1-$E$4)*(D12+E12) -> 128.35348 | E13: =$H$4*(D13-D12)+(1-$H$4)*E12 -> 8.8062288 | F13: =D12+E12 -> 131.53477 | G13: =C13-F13 -> -3.5347724 | H13: =ABS(G13) -> 3.5347724 | I13: =G13^2 -> 12.494616 | J13: =ABS(G13/C13)*100 -> 2.7615409
A14: 6 | B14: ='Data Mentah'!B11 -> 06/02/2023 | C14: ='Data Mentah'!C11 -> 130 | D14: =$E$4*C14+(1-$E$4)*(D13+E13) -> 130.71597 | E14: =$H$4*(D14-D13)+(1-$H$4)*E13 -> 8.1618553 | F14: =D13+E13 -> 137.15971 | G14: =C14-F14 -> -7.159706 | H14: =ABS(G14) -> 7.159706 | I14: =G14^2 -> 51.26139 | J14: =ABS(G14/C14)*100 -> 5.5074662
A15: 7 | B15: ='Data Mentah'!B12 -> 13/02/2023 | C15: ='Data Mentah'!C12 -> 125 | D15: =$E$4*C15+(1-$E$4)*(D14+E14) -> 126.38778 | E15: =$H$4*(D15-D14)+(1-$H$4)*E14 -> 6.9128509 | F15: =D14+E14 -> 138.87783 | G15: =C15-F15 -> -13.877826 | H15: =ABS(G15) -> 13.877826 | I15: =G15^2 -> 192.59405 | J15: =ABS(G15/C15)*100 -> 11.102261
A16: 8 | B16: ='Data Mentah'!B13 -> 20/02/2023 | C16: ='Data Mentah'!C13 -> 131 | D16: =$E$4*C16+(1-$E$4)*(D15+E15) -> 131.23006 | E16: =$H$4*(D16-D15)+(1-$H$4)*E15 -> 6.7057939 | F16: =D15+E15 -> 133.30063 | G16: =C16-F16 -> -2.3006335 | H16: =ABS(G16) -> 2.3006335 | I16: =G16^2 -> 5.2929145 | J16: =ABS(G16/C16)*100 -> 1.7562088
A17: 9 | B17: ='Data Mentah'!B14 -> 27/02/2023 | C17: ='Data Mentah'!C14 -> 121 | D17: =$E$4*C17+(1-$E$4)*(D16+E16) -> 122.69359 | E17: =$H$4*(D17-D16)+(1-$H$4)*E16 -> 5.1815668 | F17: =D16+E16 -> 137.93586 | G17: =C17-F17 -> -16.935857 | H17: =ABS(G17) -> 16.935857 | I17: =G17^2 -> 286.82326 | J17: =ABS(G17/C17)*100 -> 13.996576
A18: 10 | B18: ='Data Mentah'!B15 -> 06/03/2023 | C18: ='Data Mentah'!C15 -> 110 | D18: =$E$4*C18+(1-$E$4)*(D17+E17) -> 111.78752 | E18: =$H$4*(D18-D17)+(1-$H$4)*E17 -> 3.572803 | F18: =D17+E17 -> 127.87515 | G18: =C18-F18 -> -17.875152 | H18: =ABS(G18) -> 17.875152 | I18: =G18^2 -> 319.52108 | J18: =ABS(G18/C18)*100 -> 16.250139
A19: 11 | B19: ='Data Mentah'!B16 -> 13/03/2023 | C19: ='Data Mentah'!C16 -> 107 | D19: =$E$4*C19+(1-$E$4)*(D18+E18) -> 107.83603 | E19: =$H$4*(D19-D18)+(1-$H$4)*E18 -> 2.8203744 | F19: =D18+E18 -> 115.36032 | G19: =C19-F19 -> -8.3603183 | H19: =ABS(G19) -> 8.3603183 | I19: =G19^2 -> 69.894922 | J19: =ABS(G19/C19)*100 -> 7.8133816
A20: 12 | B20: ='Data Mentah'!B17 -> 20/03/2023 | C20: ='Data Mentah'!C17 -> 106 | D20: =$E$4*C20+(1-$E$4)*(D19+E19) -> 106.46564 | E20: =$H$4*(D20-D19)+(1-$H$4)*E19 -> 2.4012978 | F20: =D19+E19 -> 110.65641 | G20: =C20-F20 -> -4.6564062 | H20: =ABS(G20) -> 4.6564062 | I20: =G20^2 -> 21.682119 | J20: =ABS(G20/C20)*100 -> 4.3928361
... A113: 105 | B113: ='Data Mentah'!B110 -> 30/12/2024 | C113: ='Data Mentah'!C110 -> 109 | D113: =$E$4*C113+(1-$E$4)*(D112+E112) -> 110.84469 | E113: =$H$4*(D113-D112)+(1-$H$4)*E112 -> -0.93110269 | F113: =D112+E112 -> 127.44689 | G113: =C113-F113 -> -18.446891 | H113: =ABS(G113) -> 18.446891 | I113: =G113^2 -> 340.2878 | J113: =ABS(G113/C113)*100 -> 16.923753
A115: RINGKASAN EVALUASI (Data Uji — 21 Minggu Terakhir)
A116: MAD (Mean Absolute Deviation) | D116: =AVERAGE(H93:H113) -> 5.7940028
A117: MSE (Mean Squared Error) | D117: =AVERAGE(I93:I113) -> 55.511982
A118: MAPE (Mean Absolute Percentage Error) % | D118: =AVERAGE(J93:J113) -> 4.9199932
A119: Kategori (Tabel 2.1) | D119: =IF(D118<10,"Sangat Baik",IF(D118<20,"Baik",IF(D118<=50,"Cukup","Rendah"))) -> Sangat Baik
A120: Prediksi Periode ke-106 | D120: =D113+E113 -> 109.91359
A121: Rata-rata Historis (105 minggu) | D121: =AVERAGE(C9:C113) -> 116.74286

Sheet DES_Asam Mefenamat
A1: PERHITUNGAN DOUBLE EXPONENTIAL SMOOTHING — ASAM MEFENAMAT
A2: Rumus hidup: Level_t = α·Aktual_t + (1-α)·(Level_(t-1)+Tren_(t-1)); Tren_t = β·(Level_t-Level_(t-1)) + (1-β)·Tren_(t-1); Ramalan_t = Level_(t-1)+Tren_(t-1). Ubah α/β di bawah untuk menguji kombinasi lain — seluruh tabel & ringkasan terhitung ulang otomatis.
A4: Nama Obat: | B4: Asam Mefenamat | D4: Alpha (α): | E4: 0.4 | G4: Beta (β): | H4: 0.1
A5: L0 (Level Awal): | B5: ='Data Mentah'!D5 -> 25 | D5: T0 (Tren Awal): | E5: 0
A7: Periode | B7: Minggu | C7: Aktual | D7: Level | E7: Tren | F7: Ramalan | G7: Error | H7: |Error| | I7: Error² | J7: APE (%)
A8: 0 | B8: ='Data Mentah'!B5 -> 26/12/2022 | C8: ='Data Mentah'!D5 -> 25 | D8: =$B$5 -> 25 | E8: =$E$5 -> 0
A9: 1 | B9: ='Data Mentah'!B6 -> 02/01/2023 | C9: ='Data Mentah'!D6 -> 54 | D9: =$E$4*C9+(1-$E$4)*(D8+E8) -> 36.6 | E9: =$H$4*(D9-D8)+(1-$H$4)*E8 -> 1.16 | F9: =D8+E8 -> 25 | G9: =C9-F9 -> 29 | H9: =ABS(G9) -> 29 | I9: =G9^2 -> 841 | J9: =ABS(G9/C9)*100 -> 53.703704
A10: 2 | B10: ='Data Mentah'!B7 -> 09/01/2023 | C10: ='Data Mentah'!D7 -> 80 | D10: =$E$4*C10+(1-$E$4)*(D9+E9) -> 54.656 | E10: =$H$4*(D10-D9)+(1-$H$4)*E9 -> 2.8496 | F10: =D9+E9 -> 37.76 | G10: =C10-F10 -> 42.24 | H10: =ABS(G10) -> 42.24 | I10: =G10^2 -> 1784.2176 | J10: =ABS(G10/C10)*100 -> 52.8
A11: 3 | B11: ='Data Mentah'!B8 -> 16/01/2023 | C11: ='Data Mentah'!D8 -> 89 | D11: =$E$4*C11+(1-$E$4)*(D10+E10) -> 70.10336 | E11: =$H$4*(D11-D10)+(1-$H$4)*E10 -> 4.109376 | F11: =D10+E10 -> 57.5056 | G11: =C11-F11 -> 31.4944 | H11: =ABS(G11) -> 31.4944 | I11: =G11^2 -> 991.89723 | J11: =ABS(G11/C11)*100 -> 35.386966
A12: 4 | B12: ='Data Mentah'!B9 -> 23/01/2023 | C12: ='Data Mentah'!D9 -> 114 | D12: =$E$4*C12+(1-$E$4)*(D11+E11) -> 90.127642 | E12: =$H$4*(D12-D11)+(1-$H$4)*E11 -> 5.7008666 | F12: =D11+E11 -> 74.212736 | G12: =C12-F12 -> 39.787264 | H12: =ABS(G12) -> 39.787264 | I12: =G12^2 -> 1583.0264 | J12: =ABS(G12/C12)*100 -> 34.901109
A13: 5 | B13: ='Data Mentah'!B10 -> 30/01/2023 | C13: ='Data Mentah'!D10 -> 123 | D13: =$E$4*C13+(1-$E$4)*(D12+E12) -> 106.6971 | E13: =$H$4*(D13-D12)+(1-$H$4)*E12 -> 6.7877262 | F13: =D12+E12 -> 95.828508 | G13: =C13-F13 -> 27.171492 | H13: =ABS(G13) -> 27.171492 | I13: =G13^2 -> 738.28997 | J13: =ABS(G13/C13)*100 -> 22.090644
A14: 6 | B14: ='Data Mentah'!B11 -> 06/02/2023 | C14: ='Data Mentah'!D11 -> 129 | D14: =$E$4*C14+(1-$E$4)*(D13+E13) -> 119.6909 | E14: =$H$4*(D14-D13)+(1-$H$4)*E13 -> 7.408333 | F14: =D13+E13 -> 113.48483 | G14: =C14-F14 -> 15.515169 | H14: =ABS(G14) -> 15.515169 | I14: =G14^2 -> 240.72047 | J14: =ABS(G14/C14)*100 -> 12.027263
A15: 7 | B15: ='Data Mentah'!B12 -> 13/02/2023 | C15: ='Data Mentah'!D12 -> 118 | D15: =$E$4*C15+(1-$E$4)*(D14+E14) -> 123.45954 | E15: =$H$4*(D15-D14)+(1-$H$4)*E14 -> 7.0443637 | F15: =D14+E14 -> 127.09923 | G15: =C15-F15 -> -9.0992317 | H15: =ABS(G15) -> 9.0992317 | I15: =G15^2 -> 82.796017 | J15: =ABS(G15/C15)*100 -> 7.7112133
A16: 8 | B16: ='Data Mentah'!B13 -> 20/02/2023 | C16: ='Data Mentah'!D13 -> 117 | D16: =$E$4*C16+(1-$E$4)*(D15+E15) -> 125.10234 | E16: =$H$4*(D16-D15)+(1-$H$4)*E15 -> 6.5042076 | F16: =D15+E15 -> 130.5039 | G16: =C16-F16 -> -13.503903 | H16: =ABS(G16) -> 13.503903 | I16: =G16^2 -> 182.35539 | J16: =ABS(G16/C16)*100 -> 11.541797
A17: 9 | B17: ='Data Mentah'!B14 -> 27/02/2023 | C17: ='Data Mentah'!D14 -> 116 | D17: =$E$4*C17+(1-$E$4)*(D16+E16) -> 125.36393 | E17: =$H$4*(D17-D16)+(1-$H$4)*E16 -> 5.8799456 | F17: =D16+E16 -> 131.60655 | G17: =C17-F17 -> -15.606549 | H17: =ABS(G17) -> 15.606549 | I17: =G17^2 -> 243.56438 | J17: =ABS(G17/C17)*100 -> 13.453922
A18: 10 | B18: ='Data Mentah'!B15 -> 06/03/2023 | C18: ='Data Mentah'!D15 -> 108 | D18: =$E$4*C18+(1-$E$4)*(D17+E17) -> 121.94633 | E18: =$H$4*(D18-D17)+(1-$H$4)*E17 -> 4.9501906 | F18: =D17+E17 -> 131.24388 | G18: =C18-F18 -> -23.243875 | H18: =ABS(G18) -> 23.243875 | I18: =G18^2 -> 540.27773 | J18: =ABS(G18/C18)*100 -> 21.522107
A19: 11 | B19: ='Data Mentah'!B16 -> 13/03/2023 | C19: ='Data Mentah'!D16 -> 113 | D19: =$E$4*C19+(1-$E$4)*(D18+E18) -> 121.33791 | E19: =$H$4*(D19-D18)+(1-$H$4)*E18 -> 4.39433 | F19: =D18+E18 -> 126.89652 | G19: =C19-F19 -> -13.896516 | H19: =ABS(G19) -> 13.896516 | I19: =G19^2 -> 193.11315 | J19: =ABS(G19/C19)*100 -> 12.297802
A20: 12 | B20: ='Data Mentah'!B17 -> 20/03/2023 | C20: ='Data Mentah'!D17 -> 106 | D20: =$E$4*C20+(1-$E$4)*(D19+E19) -> 117.83934 | E20: =$H$4*(D20-D19)+(1-$H$4)*E19 -> 3.6050404 | F20: =D19+E19 -> 125.73224 | G20: =C20-F20 -> -19.732239 | H20: =ABS(G20) -> 19.732239 | I20: =G20^2 -> 389.36127 | J20: =ABS(G20/C20)*100 -> 18.61532
... A113: 105 | B113: ='Data Mentah'!B110 -> 30/12/2024 | C113: ='Data Mentah'!D110 -> 106 | D113: =$E$4*C113+(1-$E$4)*(D112+E112) -> 114.29451 | E113: =$H$4*(D113-D112)+(1-$H$4)*E112 -> -0.58918946 | F113: =D112+E112 -> 119.82419 | G113: =C113-F113 -> -13.824185 | H113: =ABS(G113) -> 13.824185 | I113: =G113^2 -> 191.1081 | J113: =ABS(G113/C113)*100 -> 13.041684
A115: RINGKASAN EVALUASI (Data Uji — 21 Minggu Terakhir)
A116: MAD (Mean Absolute Deviation) | D116: =AVERAGE(H93:H113) -> 7.3738089
A117: MSE (Mean Squared Error) | D117: =AVERAGE(I93:I113) -> 90.098434
A118: MAPE (Mean Absolute Percentage Error) % | D118: =AVERAGE(J93:J113) -> 6.3586962
A119: Kategori (Tabel 2.1) | D119: =IF(D118<10,"Sangat Baik",IF(D118<20,"Baik",IF(D118<=50,"Cukup","Rendah"))) -> Sangat Baik
A120: Prediksi Periode ke-106 | D120: =D113+E113 -> 113.70532
A121: Rata-rata Historis (105 minggu) | D121: =AVERAGE(C9:C113) -> 116.41905

Sheet DES_Amoxicillin
A1: PERHITUNGAN DOUBLE EXPONENTIAL SMOOTHING — AMOXICILLIN
A2: Rumus hidup: Level_t = α·Aktual_t + (1-α)·(Level_(t-1)+Tren_(t-1)); Tren_t = β·(Level_t-Level_(t-1)) + (1-β)·Tren_(t-1); Ramalan_t = Level_(t-1)+Tren_(t-1). Ubah α/β di bawah untuk menguji kombinasi lain — seluruh tabel & ringkasan terhitung ulang otomatis.
A4: Nama Obat: | B4: Amoxicillin | D4: Alpha (α): | E4: 0.1 | G4: Beta (β): | H4: 0.3
A5: L0 (Level Awal): | B5: ='Data Mentah'!E5 -> 15 | D5: T0 (Tren Awal): | E5: 0
A7: Periode | B7: Minggu | C7: Aktual | D7: Level | E7: Tren | F7: Ramalan | G7: Error | H7: |Error| | I7: Error² | J7: APE (%)
A8: 0 | B8: ='Data Mentah'!B5 -> 26/12/2022 | C8: ='Data Mentah'!E5 -> 15 | D8: =$B$5 -> 15 | E8: =$E$5 -> 0
A9: 1 | B9: ='Data Mentah'!B6 -> 02/01/2023 | C9: ='Data Mentah'!E6 -> 69 | D9: =$E$4*C9+(1-$E$4)*(D8+E8) -> 20.4 | E9: =$H$4*(D9-D8)+(1-$H$4)*E8 -> 1.62 | F9: =D8+E8 -> 15 | G9: =C9-F9 -> 54 | H9: =ABS(G9) -> 54 | I9: =G9^2 -> 2916 | J9: =ABS(G9/C9)*100 -> 78.26087
A10: 2 | B10: ='Data Mentah'!B7 -> 09/01/2023 | C10: ='Data Mentah'!E7 -> 75 | D10: =$E$4*C10+(1-$E$4)*(D9+E9) -> 27.318 | E10: =$H$4*(D10-D9)+(1-$H$4)*E9 -> 3.2094 | F10: =D9+E9 -> 22.02 | G10: =C10-F10 -> 52.98 | H10: =ABS(G10) -> 52.98 | I10: =G10^2 -> 2806.8804 | J10: =ABS(G10/C10)*100 -> 70.64
A11: 3 | B11: ='Data Mentah'!B8 -> 16/01/2023 | C11: ='Data Mentah'!E8 -> 95 | D11: =$E$4*C11+(1-$E$4)*(D10+E10) -> 36.97466 | E11: =$H$4*(D11-D10)+(1-$H$4)*E10 -> 5.143578 | F11: =D10+E10 -> 30.5274 | G11: =C11-F11 -> 64.4726 | H11: =ABS(G11) -> 64.4726 | I11: =G11^2 -> 4156.7162 | J11: =ABS(G11/C11)*100 -> 67.865895
A12: 4 | B12: ='Data Mentah'!B9 -> 23/01/2023 | C12: ='Data Mentah'!E9 -> 121 | D12: =$E$4*C12+(1-$E$4)*(D11+E11) -> 50.006414 | E12: =$H$4*(D12-D11)+(1-$H$4)*E11 -> 7.5100309 | F12: =D11+E11 -> 42.118238 | G12: =C12-F12 -> 78.881762 | H12: =ABS(G12) -> 78.881762 | I12: =G12^2 -> 6222.3324 | J12: =ABS(G12/C12)*100 -> 65.191539
A13: 5 | B13: ='Data Mentah'!B10 -> 30/01/2023 | C13: ='Data Mentah'!E10 -> 116 | D13: =$E$4*C13+(1-$E$4)*(D12+E12) -> 63.364801 | E13: =$H$4*(D13-D12)+(1-$H$4)*E12 -> 9.2645375 | F13: =D12+E12 -> 57.516445 | G13: =C13-F13 -> 58.483555 | H13: =ABS(G13) -> 58.483555 | I13: =G13^2 -> 3420.3262 | J13: =ABS(G13/C13)*100 -> 50.416858
A14: 6 | B14: ='Data Mentah'!B11 -> 06/02/2023 | C14: ='Data Mentah'!E11 -> 120 | D14: =$E$4*C14+(1-$E$4)*(D13+E13) -> 77.366404 | E14: =$H$4*(D14-D13)+(1-$H$4)*E13 -> 10.685657 | F14: =D13+E13 -> 72.629338 | G14: =C14-F14 -> 47.370662 | H14: =ABS(G14) -> 47.370662 | I14: =G14^2 -> 2243.9796 | J14: =ABS(G14/C14)*100 -> 39.475552
A15: 7 | B15: ='Data Mentah'!B12 -> 13/02/2023 | C15: ='Data Mentah'!E12 -> 109 | D15: =$E$4*C15+(1-$E$4)*(D14+E14) -> 90.146855 | E15: =$H$4*(D15-D14)+(1-$H$4)*E14 -> 11.314096 | F15: =D14+E14 -> 88.052062 | G15: =C15-F15 -> 20.947938 | H15: =ABS(G15) -> 20.947938 | I15: =G15^2 -> 438.81612 | J15: =ABS(G15/C15)*100 -> 19.218292
A16: 8 | B16: ='Data Mentah'!B13 -> 20/02/2023 | C16: ='Data Mentah'!E13 -> 105 | D16: =$E$4*C16+(1-$E$4)*(D15+E15) -> 101.81486 | E16: =$H$4*(D16-D15)+(1-$H$4)*E15 -> 11.420267 | F16: =D15+E15 -> 101.46095 | G16: =C16-F16 -> 3.539049 | H16: =ABS(G16) -> 3.539049 | I16: =G16^2 -> 12.524868 | J16: =ABS(G16/C16)*100 -> 3.3705229
A17: 9 | B17: ='Data Mentah'!B14 -> 27/02/2023 | C17: ='Data Mentah'!E14 -> 104 | D17: =$E$4*C17+(1-$E$4)*(D16+E16) -> 112.31161 | E17: =$H$4*(D17-D16)+(1-$H$4)*E16 -> 11.143213 | F17: =D16+E16 -> 113.23512 | G17: =C17-F17 -> -9.2351229 | H17: =ABS(G17) -> 9.2351229 | I17: =G17^2 -> 85.287494 | J17: =ABS(G17/C17)*100 -> 8.8799258
A18: 10 | B18: ='Data Mentah'!B15 -> 06/03/2023 | C18: ='Data Mentah'!E15 -> 115 | D18: =$E$4*C18+(1-$E$4)*(D17+E17) -> 122.60934 | E18: =$H$4*(D18-D17)+(1-$H$4)*E17 -> 10.889569 | F18: =D17+E17 -> 123.45482 | G18: =C18-F18 -> -8.4548239 | H18: =ABS(G18) -> 8.4548239 | I18: =G18^2 -> 71.484047 | J18: =ABS(G18/C18)*100 -> 7.3520208
A19: 11 | B19: ='Data Mentah'!B16 -> 13/03/2023 | C19: ='Data Mentah'!E16 -> 126 | D19: =$E$4*C19+(1-$E$4)*(D18+E18) -> 132.74902 | E19: =$H$4*(D19-D18)+(1-$H$4)*E18 -> 10.664601 | F19: =D18+E18 -> 133.49891 | G19: =C19-F19 -> -7.4989101 | H19: =ABS(G19) -> 7.4989101 | I19: =G19^2 -> 56.233652 | J19: =ABS(G19/C19)*100 -> 5.9515159
A20: 12 | B20: ='Data Mentah'!B17 -> 20/03/2023 | C20: ='Data Mentah'!E17 -> 133 | D20: =$E$4*C20+(1-$E$4)*(D19+E19) -> 142.37226 | E20: =$H$4*(D20-D19)+(1-$H$4)*E19 -> 10.352193 | F20: =D19+E19 -> 143.41362 | G20: =C20-F20 -> -10.41362 | H20: =ABS(G20) -> 10.41362 | I20: =G20^2 -> 108.44349 | J20: =ABS(G20/C20)*100 -> 7.8297897
... A113: 105 | B113: ='Data Mentah'!B110 -> 30/12/2024 | C113: ='Data Mentah'!E110 -> 100 | D113: =$E$4*C113+(1-$E$4)*(D112+E112) -> 114.03636 | E113: =$H$4*(D113-D112)+(1-$H$4)*E112 -> 0.041477458 | F113: =D112+E112 -> 115.59596 | G113: =C113-F113 -> -15.595961 | H113: =ABS(G113) -> 15.595961 | I113: =G113^2 -> 243.23399 | J113: =ABS(G113/C113)*100 -> 15.595961
A115: RINGKASAN EVALUASI (Data Uji — 21 Minggu Terakhir)
A116: MAD (Mean Absolute Deviation) | D116: =AVERAGE(H93:H113) -> 6.3515407
A117: MSE (Mean Squared Error) | D117: =AVERAGE(I93:I113) -> 61.202657
A118: MAPE (Mean Absolute Percentage Error) % | D118: =AVERAGE(J93:J113) -> 5.6328216
A119: Kategori (Tabel 2.1) | D119: =IF(D118<10,"Sangat Baik",IF(D118<20,"Baik",IF(D118<=50,"Cukup","Rendah"))) -> Sangat Baik
A120: Prediksi Periode ke-106 | D120: =D113+E113 -> 114.07784
A121: Rata-rata Historis (105 minggu) | D121: =AVERAGE(C9:C113) -> 116.49524

Sheet DES_Naturoksi
A1: PERHITUNGAN DOUBLE EXPONENTIAL SMOOTHING — NATUROKSI
A2: Rumus hidup: Level_t = α·Aktual_t + (1-α)·(Level_(t-1)+Tren_(t-1)); Tren_t = β·(Level_t-Level_(t-1)) + (1-β)·Tren_(t-1); Ramalan_t = Level_(t-1)+Tren_(t-1). Ubah α/β di bawah untuk menguji kombinasi lain — seluruh tabel & ringkasan terhitung ulang otomatis.
A4: Nama Obat: | B4: Naturoksi | D4: Alpha (α): | E4: 0.9 | G4: Beta (β): | H4: 0.1
A5: L0 (Level Awal): | B5: ='Data Mentah'!F5 -> 28 | D5: T0 (Tren Awal): | E5: 0
A7: Periode | B7: Minggu | C7: Aktual | D7: Level | E7: Tren | F7: Ramalan | G7: Error | H7: |Error| | I7: Error² | J7: APE (%)
A8: 0 | B8: ='Data Mentah'!B5 -> 26/12/2022 | C8: ='Data Mentah'!F5 -> 28 | D8: =$B$5 -> 28 | E8: =$E$5 -> 0
A9: 1 | B9: ='Data Mentah'!B6 -> 02/01/2023 | C9: ='Data Mentah'!F6 -> 80 | D9: =$E$4*C9+(1-$E$4)*(D8+E8) -> 74.8 | E9: =$H$4*(D9-D8)+(1-$H$4)*E8 -> 4.68 | F9: =D8+E8 -> 28 | G9: =C9-F9 -> 52 | H9: =ABS(G9) -> 52 | I9: =G9^2 -> 2704 | J9: =ABS(G9/C9)*100 -> 65
A10: 2 | B10: ='Data Mentah'!B7 -> 09/01/2023 | C10: ='Data Mentah'!F7 -> 104 | D10: =$E$4*C10+(1-$E$4)*(D9+E9) -> 101.548 | E10: =$H$4*(D10-D9)+(1-$H$4)*E9 -> 6.8868 | F10: =D9+E9 -> 79.48 | G10: =C10-F10 -> 24.52 | H10: =ABS(G10) -> 24.52 | I10: =G10^2 -> 601.2304 | J10: =ABS(G10/C10)*100 -> 23.576923
A11: 3 | B11: ='Data Mentah'!B8 -> 16/01/2023 | C11: ='Data Mentah'!F8 -> 106 | D11: =$E$4*C11+(1-$E$4)*(D10+E10) -> 106.24348 | E11: =$H$4*(D11-D10)+(1-$H$4)*E10 -> 6.667668 | F11: =D10+E10 -> 108.4348 | G11: =C11-F11 -> -2.4348 | H11: =ABS(G11) -> 2.4348 | I11: =G11^2 -> 5.928251 | J11: =ABS(G11/C11)*100 -> 2.2969811
A12: 4 | B12: ='Data Mentah'!B9 -> 23/01/2023 | C12: ='Data Mentah'!F9 -> 127 | D12: =$E$4*C12+(1-$E$4)*(D11+E11) -> 125.59111 | E12: =$H$4*(D12-D11)+(1-$H$4)*E11 -> 7.9356647 | F12: =D11+E11 -> 112.91115 | G12: =C12-F12 -> 14.088852 | H12: =ABS(G12) -> 14.088852 | I12: =G12^2 -> 198.49575 | J12: =ABS(G12/C12)*100 -> 11.093584
A13: 5 | B13: ='Data Mentah'!B10 -> 30/01/2023 | C13: ='Data Mentah'!F10 -> 127 | D13: =$E$4*C13+(1-$E$4)*(D12+E12) -> 127.65268 | E13: =$H$4*(D13-D12)+(1-$H$4)*E12 -> 7.3482545 | F13: =D12+E12 -> 133.52678 | G13: =C13-F13 -> -6.5267795 | H13: =ABS(G13) -> 6.5267795 | I13: =G13^2 -> 42.59885 | J13: =ABS(G13/C13)*100 -> 5.1391964
A14: 6 | B14: ='Data Mentah'!B11 -> 06/02/2023 | C14: ='Data Mentah'!F11 -> 121 | D14: =$E$4*C14+(1-$E$4)*(D13+E13) -> 122.40009 | E14: =$H$4*(D14-D13)+(1-$H$4)*E13 -> 6.0881706 | F14: =D13+E13 -> 135.00093 | G14: =C14-F14 -> -14.000932 | H14: =ABS(G14) -> 14.000932 | I14: =G14^2 -> 196.02611 | J14: =ABS(G14/C14)*100 -> 11.571019
A15: 7 | B15: ='Data Mentah'!B12 -> 13/02/2023 | C15: ='Data Mentah'!F12 -> 118 | D15: =$E$4*C15+(1-$E$4)*(D14+E14) -> 119.04883 | E15: =$H$4*(D15-D14)+(1-$H$4)*E14 -> 5.1442269 | F15: =D14+E14 -> 128.48826 | G15: =C15-F15 -> -10.488264 | H15: =ABS(G15) -> 10.488264 | I15: =G15^2 -> 110.00368 | J15: =ABS(G15/C15)*100 -> 8.8883592
A16: 8 | B16: ='Data Mentah'!B13 -> 20/02/2023 | C16: ='Data Mentah'!F13 -> 114 | D16: =$E$4*C16+(1-$E$4)*(D15+E15) -> 115.01931 | E16: =$H$4*(D16-D15)+(1-$H$4)*E15 -> 4.2268521 | F16: =D15+E15 -> 124.19305 | G16: =C16-F16 -> -10.193053 | H16: =ABS(G16) -> 10.193053 | I16: =G16^2 -> 103.89833 | J16: =ABS(G16/C16)*100 -> 8.9412748
A17: 9 | B17: ='Data Mentah'!B14 -> 27/02/2023 | C17: ='Data Mentah'!F14 -> 111 | D17: =$E$4*C17+(1-$E$4)*(D16+E16) -> 111.82462 | E17: =$H$4*(D17-D16)+(1-$H$4)*E16 -> 3.4846979 | F17: =D16+E16 -> 119.24616 | G17: =C17-F17 -> -8.2461574 | H17: =ABS(G17) -> 8.2461574 | I17: =G17^2 -> 67.999112 | J17: =ABS(G17/C17)*100 -> 7.4289706
A18: 10 | B18: ='Data Mentah'!B15 -> 06/03/2023 | C18: ='Data Mentah'!F15 -> 101 | D18: =$E$4*C18+(1-$E$4)*(D17+E17) -> 102.43093 | E18: =$H$4*(D18-D17)+(1-$H$4)*E17 -> 2.1968597 | F18: =D17+E17 -> 115.30931 | G18: =C18-F18 -> -14.309314 | H18: =ABS(G18) -> 14.309314 | I18: =G18^2 -> 204.75646 | J18: =ABS(G18/C18)*100 -> 14.167637
A19: 11 | B19: ='Data Mentah'!B16 -> 13/03/2023 | C19: ='Data Mentah'!F16 -> 99 | D19: =$E$4*C19+(1-$E$4)*(D18+E18) -> 99.562779 | E19: =$H$4*(D19-D18)+(1-$H$4)*E18 -> 1.6903585 | F19: =D18+E18 -> 104.62779 | G19: =C19-F19 -> -5.627791 | H19: =ABS(G19) -> 5.627791 | I19: =G19^2 -> 31.672032 | J19: =ABS(G19/C19)*100 -> 5.6846374
A20: 12 | B20: ='Data Mentah'!B17 -> 20/03/2023 | C20: ='Data Mentah'!F17 -> 108 | D20: =$E$4*C20+(1-$E$4)*(D19+E19) -> 107.32531 | E20: =$H$4*(D20-D19)+(1-$H$4)*E19 -> 2.2975761 | F20: =D19+E19 -> 101.25314 | G20: =C20-F20 -> 6.7468624 | H20: =ABS(G20) -> 6.7468624 | I20: =G20^2 -> 45.520152 | J20: =ABS(G20/C20)*100 -> 6.2470948
... A113: 105 | B113: ='Data Mentah'!B110 -> 30/12/2024 | C113: ='Data Mentah'!F110 -> 93 | D113: =$E$4*C113+(1-$E$4)*(D112+E112) -> 96.524372 | E113: =$H$4*(D113-D112)+(1-$H$4)*E112 -> -3.3132756 | F113: =D112+E112 -> 128.24372 | G113: =C113-F113 -> -35.24372 | H113: =ABS(G113) -> 35.24372 | I113: =G113^2 -> 1242.1198 | J113: =ABS(G113/C113)*100 -> 37.896473
A115: RINGKASAN EVALUASI (Data Uji — 21 Minggu Terakhir)
A116: MAD (Mean Absolute Deviation) | D116: =AVERAGE(H93:H113) -> 6.3351949
A117: MSE (Mean Squared Error) | D117: =AVERAGE(I93:I113) -> 97.291858
A118: MAPE (Mean Absolute Percentage Error) % | D118: =AVERAGE(J93:J113) -> 5.4497206
A119: Kategori (Tabel 2.1) | D119: =IF(D118<10,"Sangat Baik",IF(D118<20,"Baik",IF(D118<=50,"Cukup","Rendah"))) -> Sangat Baik
A120: Prediksi Periode ke-106 | D120: =D113+E113 -> 93.211096
A121: Rata-rata Historis (105 minggu) | D121: =AVERAGE(C9:C113) -> 117.27619

Sheet DES_Gentamicin Injeksi
A1: PERHITUNGAN DOUBLE EXPONENTIAL SMOOTHING — GENTAMICIN INJEKSI
A2: Rumus hidup: Level_t = α·Aktual_t + (1-α)·(Level_(t-1)+Tren_(t-1)); Tren_t = β·(Level_t-Level_(t-1)) + (1-β)·Tren_(t-1); Ramalan_t = Level_(t-1)+Tren_(t-1). Ubah α/β di bawah untuk menguji kombinasi lain — seluruh tabel & ringkasan terhitung ulang otomatis.
A4: Nama Obat: | B4: Gentamicin Injeksi | D4: Alpha (α): | E4: 0.1 | G4: Beta (β): | H4: 0.2
A5: L0 (Level Awal): | B5: ='Data Mentah'!G5 -> 7 | D5: T0 (Tren Awal): | E5: 0
A7: Periode | B7: Minggu | C7: Aktual | D7: Level | E7: Tren | F7: Ramalan | G7: Error | H7: |Error| | I7: Error² | J7: APE (%)
A8: 0 | B8: ='Data Mentah'!B5 -> 26/12/2022 | C8: ='Data Mentah'!G5 -> 7 | D8: =$B$5 -> 7 | E8: =$E$5 -> 0
A9: 1 | B9: ='Data Mentah'!B6 -> 02/01/2023 | C9: ='Data Mentah'!G6 -> 37 | D9: =$E$4*C9+(1-$E$4)*(D8+E8) -> 10 | E9: =$H$4*(D9-D8)+(1-$H$4)*E8 -> 0.6 | F9: =D8+E8 -> 7 | G9: =C9-F9 -> 30 | H9: =ABS(G9) -> 30 | I9: =G9^2 -> 900 | J9: =ABS(G9/C9)*100 -> 81.081081
A10: 2 | B10: ='Data Mentah'!B7 -> 09/01/2023 | C10: ='Data Mentah'!G7 -> 63 | D10: =$E$4*C10+(1-$E$4)*(D9+E9) -> 15.84 | E10: =$H$4*(D10-D9)+(1-$H$4)*E9 -> 1.648 | F10: =D9+E9 -> 10.6 | G10: =C10-F10 -> 52.4 | H10: =ABS(G10) -> 52.4 | I10: =G10^2 -> 2745.76 | J10: =ABS(G10/C10)*100 -> 83.174603
A11: 3 | B11: ='Data Mentah'!B8 -> 16/01/2023 | C11: ='Data Mentah'!G8 -> 78 | D11: =$E$4*C11+(1-$E$4)*(D10+E10) -> 23.5392 | E11: =$H$4*(D11-D10)+(1-$H$4)*E10 -> 2.85824 | F11: =D10+E10 -> 17.488 | G11: =C11-F11 -> 60.512 | H11: =ABS(G11) -> 60.512 | I11: =G11^2 -> 3661.7021 | J11: =ABS(G11/C11)*100 -> 77.579487
A12: 4 | B12: ='Data Mentah'!B9 -> 23/01/2023 | C12: ='Data Mentah'!G9 -> 109 | D12: =$E$4*C12+(1-$E$4)*(D11+E11) -> 34.657696 | E12: =$H$4*(D12-D11)+(1-$H$4)*E11 -> 4.5102912 | F12: =D11+E11 -> 26.39744 | G12: =C12-F12 -> 82.60256 | H12: =ABS(G12) -> 82.60256 | I12: =G12^2 -> 6823.1829 | J12: =ABS(G12/C12)*100 -> 75.782165
A13: 5 | B13: ='Data Mentah'!B10 -> 30/01/2023 | C13: ='Data Mentah'!G10 -> 133 | D13: =$E$4*C13+(1-$E$4)*(D12+E12) -> 48.551188 | E13: =$H$4*(D13-D12)+(1-$H$4)*E12 -> 6.3869315 | F13: =D12+E12 -> 39.167987 | G13: =C13-F13 -> 93.832013 | H13: =ABS(G13) -> 93.832013 | I13: =G13^2 -> 8804.4466 | J13: =ABS(G13/C13)*100 -> 70.550386
A14: 6 | B14: ='Data Mentah'!B11 -> 06/02/2023 | C14: ='Data Mentah'!G11 -> 131 | D14: =$E$4*C14+(1-$E$4)*(D13+E13) -> 62.544308 | E14: =$H$4*(D14-D13)+(1-$H$4)*E13 -> 7.9081691 | F14: =D13+E13 -> 54.93812 | G14: =C14-F14 -> 76.06188 | H14: =ABS(G14) -> 76.06188 | I14: =G14^2 -> 5785.4096 | J14: =ABS(G14/C14)*100 -> 58.062504
A15: 7 | B15: ='Data Mentah'!B12 -> 13/02/2023 | C15: ='Data Mentah'!G12 -> 130 | D15: =$E$4*C15+(1-$E$4)*(D14+E14) -> 76.407229 | E15: =$H$4*(D15-D14)+(1-$H$4)*E14 -> 9.0991195 | F15: =D14+E14 -> 70.452477 | G15: =C15-F15 -> 59.547523 | H15: =ABS(G15) -> 59.547523 | I15: =G15^2 -> 3545.9075 | J15: =ABS(G15/C15)*100 -> 45.805787
A16: 8 | B16: ='Data Mentah'!B13 -> 20/02/2023 | C16: ='Data Mentah'!G13 -> 127 | D16: =$E$4*C16+(1-$E$4)*(D15+E15) -> 89.655714 | E16: =$H$4*(D16-D15)+(1-$H$4)*E15 -> 9.9289925 | F16: =D15+E15 -> 85.506349 | G16: =C16-F16 -> 41.493651 | H16: =ABS(G16) -> 41.493651 | I16: =G16^2 -> 1721.7231 | J16: =ABS(G16/C16)*100 -> 32.672166
A17: 9 | B17: ='Data Mentah'!B14 -> 27/02/2023 | C17: ='Data Mentah'!G14 -> 122 | D17: =$E$4*C17+(1-$E$4)*(D16+E16) -> 101.82624 | E17: =$H$4*(D17-D16)+(1-$H$4)*E16 -> 10.377298 | F17: =D16+E16 -> 99.584706 | G17: =C17-F17 -> 22.415294 | H17: =ABS(G17) -> 22.415294 | I17: =G17^2 -> 502.44538 | J17: =ABS(G17/C17)*100 -> 18.373191
A18: 10 | B18: ='Data Mentah'!B15 -> 06/03/2023 | C18: ='Data Mentah'!G15 -> 121 | D18: =$E$4*C18+(1-$E$4)*(D17+E17) -> 113.08318 | E18: =$H$4*(D18-D17)+(1-$H$4)*E17 -> 10.553228 | F18: =D17+E17 -> 112.20353 | G18: =C18-F18 -> 8.7964658 | H18: =ABS(G18) -> 8.7964658 | I18: =G18^2 -> 77.37781 | J18: =ABS(G18/C18)*100 -> 7.2698064
A19: 11 | B19: ='Data Mentah'!B16 -> 13/03/2023 | C19: ='Data Mentah'!G16 -> 127 | D19: =$E$4*C19+(1-$E$4)*(D18+E18) -> 123.97277 | E19: =$H$4*(D19-D18)+(1-$H$4)*E18 -> 10.6205 | F19: =D18+E18 -> 123.63641 | G19: =C19-F19 -> 3.3635915 | H19: =ABS(G19) -> 3.3635915 | I19: =G19^2 -> 11.313747 | J19: =ABS(G19/C19)*100 -> 2.6484972
A20: 12 | B20: ='Data Mentah'!B17 -> 20/03/2023 | C20: ='Data Mentah'!G17 -> 137 | D20: =$E$4*C20+(1-$E$4)*(D19+E19) -> 134.83394 | E20: =$H$4*(D20-D19)+(1-$H$4)*E19 -> 10.668634 | F20: =D19+E19 -> 134.59327 | G20: =C20-F20 -> 2.4067328 | H20: =ABS(G20) -> 2.4067328 | I20: =G20^2 -> 5.7923626 | J20: =ABS(G20/C20)*100 -> 1.7567392
... A113: 105 | B113: ='Data Mentah'!B110 -> 30/12/2024 | C113: ='Data Mentah'!G110 -> 91 | D113: =$E$4*C113+(1-$E$4)*(D112+E112) -> 112.60884 | E113: =$H$4*(D113-D112)+(1-$H$4)*E112 -> -1.0925627 | F113: =D112+E112 -> 115.00983 | G113: =C113-F113 -> -24.009827 | H113: =ABS(G113) -> 24.009827 | I113: =G113^2 -> 576.4718 | J113: =ABS(G113/C113)*100 -> 26.384425
A115: RINGKASAN EVALUASI (Data Uji — 21 Minggu Terakhir)
A116: MAD (Mean Absolute Deviation) | D116: =AVERAGE(H93:H113) -> 5.0520347
A117: MSE (Mean Squared Error) | D117: =AVERAGE(I93:I113) -> 53.647869
A118: MAPE (Mean Absolute Percentage Error) % | D118: =AVERAGE(J93:J113) -> 4.5554673
A119: Kategori (Tabel 2.1) | D119: =IF(D118<10,"Sangat Baik",IF(D118<20,"Baik",IF(D118<=50,"Cukup","Rendah"))) -> Sangat Baik
A120: Prediksi Periode ke-106 | D120: =D113+E113 -> 111.51628
A121: Rata-rata Historis (105 minggu) | D121: =AVERAGE(C9:C113) -> 119.20952

Sheet DES_Tramadol Injeksi
A1: PERHITUNGAN DOUBLE EXPONENTIAL SMOOTHING — TRAMADOL INJEKSI
A2: Rumus hidup: Level_t = α·Aktual_t + (1-α)·(Level_(t-1)+Tren_(t-1)); Tren_t = β·(Level_t-Level_(t-1)) + (1-β)·Tren_(t-1); Ramalan_t = Level_(t-1)+Tren_(t-1). Ubah α/β di bawah untuk menguji kombinasi lain — seluruh tabel & ringkasan terhitung ulang otomatis.
A4: Nama Obat: | B4: Tramadol Injeksi | D4: Alpha (α): | E4: 0.9 | G4: Beta (β): | H4: 0.9
A5: L0 (Level Awal): | B5: ='Data Mentah'!H5 -> 23 | D5: T0 (Tren Awal): | E5: 0
A7: Periode | B7: Minggu | C7: Aktual | D7: Level | E7: Tren | F7: Ramalan | G7: Error | H7: |Error| | I7: Error² | J7: APE (%)
A8: 0 | B8: ='Data Mentah'!B5 -> 26/12/2022 | C8: ='Data Mentah'!H5 -> 23 | D8: =$B$5 -> 23 | E8: =$E$5 -> 0
A9: 1 | B9: ='Data Mentah'!B6 -> 02/01/2023 | C9: ='Data Mentah'!H6 -> 71 | D9: =$E$4*C9+(1-$E$4)*(D8+E8) -> 66.2 | E9: =$H$4*(D9-D8)+(1-$H$4)*E8 -> 38.88 | F9: =D8+E8 -> 23 | G9: =C9-F9 -> 48 | H9: =ABS(G9) -> 48 | I9: =G9^2 -> 2304 | J9: =ABS(G9/C9)*100 -> 67.605634
A10: 2 | B10: ='Data Mentah'!B7 -> 09/01/2023 | C10: ='Data Mentah'!H7 -> 76 | D10: =$E$4*C10+(1-$E$4)*(D9+E9) -> 78.908 | E10: =$H$4*(D10-D9)+(1-$H$4)*E9 -> 15.3252 | F10: =D9+E9 -> 105.08 | G10: =C10-F10 -> -29.08 | H10: =ABS(G10) -> 29.08 | I10: =G10^2 -> 845.6464 | J10: =ABS(G10/C10)*100 -> 38.263158
A11: 3 | B11: ='Data Mentah'!B8 -> 16/01/2023 | C11: ='Data Mentah'!H8 -> 83 | D11: =$E$4*C11+(1-$E$4)*(D10+E10) -> 84.12332 | E11: =$H$4*(D11-D10)+(1-$H$4)*E10 -> 6.226308 | F11: =D10+E10 -> 94.2332 | G11: =C11-F11 -> -11.2332 | H11: =ABS(G11) -> 11.2332 | I11: =G11^2 -> 126.18478 | J11: =ABS(G11/C11)*100 -> 13.533976
A12: 4 | B12: ='Data Mentah'!B9 -> 23/01/2023 | C12: ='Data Mentah'!H9 -> 114 | D12: =$E$4*C12+(1-$E$4)*(D11+E11) -> 111.63496 | E12: =$H$4*(D12-D11)+(1-$H$4)*E11 -> 25.383109 | F12: =D11+E11 -> 90.349628 | G12: =C12-F12 -> 23.650372 | H12: =ABS(G12) -> 23.650372 | I12: =G12^2 -> 559.3401 | J12: =ABS(G12/C12)*100 -> 20.74594
A13: 5 | B13: ='Data Mentah'!B10 -> 30/01/2023 | C13: ='Data Mentah'!H10 -> 123 | D13: =$E$4*C13+(1-$E$4)*(D12+E12) -> 124.40181 | E13: =$H$4*(D13-D12)+(1-$H$4)*E12 -> 14.028471 | F13: =D12+E12 -> 137.01807 | G13: =C13-F13 -> -14.018072 | H13: =ABS(G13) -> 14.018072 | I13: =G13^2 -> 196.50635 | J13: =ABS(G13/C13)*100 -> 11.396807
A14: 6 | B14: ='Data Mentah'!B11 -> 06/02/2023 | C14: ='Data Mentah'!H11 -> 128 | D14: =$E$4*C14+(1-$E$4)*(D13+E13) -> 129.04303 | E14: =$H$4*(D14-D13)+(1-$H$4)*E13 -> 5.5799456 | F14: =D13+E13 -> 138.43028 | G14: =C14-F14 -> -10.430278 | H14: =ABS(G14) -> 10.430278 | I14: =G14^2 -> 108.7907 | J14: =ABS(G14/C14)*100 -> 8.1486548
A15: 7 | B15: ='Data Mentah'!B12 -> 13/02/2023 | C15: ='Data Mentah'!H12 -> 123 | D15: =$E$4*C15+(1-$E$4)*(D14+E14) -> 124.1623 | E15: =$H$4*(D15-D14)+(1-$H$4)*E14 -> -3.8346629 | F15: =D14+E14 -> 134.62297 | G15: =C15-F15 -> -11.622973 | H15: =ABS(G15) -> 11.622973 | I15: =G15^2 -> 135.09351 | J15: =ABS(G15/C15)*100 -> 9.4495719
A16: 8 | B16: ='Data Mentah'!B13 -> 20/02/2023 | C16: ='Data Mentah'!H13 -> 120 | D16: =$E$4*C16+(1-$E$4)*(D15+E15) -> 120.03276 | E16: =$H$4*(D16-D15)+(1-$H$4)*E15 -> -4.1000468 | F16: =D15+E15 -> 120.32763 | G16: =C16-F16 -> -0.32763449 | H16: =ABS(G16) -> 0.32763449 | I16: =G16^2 -> 0.10734436 | J16: =ABS(G16/C16)*100 -> 0.27302874
A17: 9 | B17: ='Data Mentah'!B14 -> 27/02/2023 | C17: ='Data Mentah'!H14 -> 106 | D17: =$E$4*C17+(1-$E$4)*(D16+E16) -> 106.99327 | E17: =$H$4*(D17-D16)+(1-$H$4)*E16 -> -12.145547 | F17: =D16+E16 -> 115.93272 | G17: =C17-F17 -> -9.9327167 | H17: =ABS(G17) -> 9.9327167 | I17: =G17^2 -> 98.65886 | J17: =ABS(G17/C17)*100 -> 9.3704874
A18: 10 | B18: ='Data Mentah'!B15 -> 06/03/2023 | C18: ='Data Mentah'!H15 -> 104 | D18: =$E$4*C18+(1-$E$4)*(D17+E17) -> 103.08477 | E18: =$H$4*(D18-D17)+(1-$H$4)*E17 -> -4.732204 | F18: =D17+E17 -> 94.847724 | G18: =C18-F18 -> 9.1522756 | H18: =ABS(G18) -> 9.1522756 | I18: =G18^2 -> 83.764149 | J18: =ABS(G18/C18)*100 -> 8.800265
A19: 11 | B19: ='Data Mentah'!B16 -> 13/03/2023 | C19: ='Data Mentah'!H16 -> 112 | D19: =$E$4*C19+(1-$E$4)*(D18+E18) -> 110.63526 | E19: =$H$4*(D19-D18)+(1-$H$4)*E18 -> 6.3222156 | F19: =D18+E18 -> 98.352568 | G19: =C19-F19 -> 13.647432 | H19: =ABS(G19) -> 13.647432 | I19: =G19^2 -> 186.25239 | J19: =ABS(G19/C19)*100 -> 12.185207
A20: 12 | B20: ='Data Mentah'!B17 -> 20/03/2023 | C20: ='Data Mentah'!H17 -> 102 | D20: =$E$4*C20+(1-$E$4)*(D19+E19) -> 103.49575 | E20: =$H$4*(D20-D19)+(1-$H$4)*E19 -> -5.7933371 | F20: =D19+E19 -> 116.95747 | G20: =C20-F20 -> -14.957472 | H20: =ABS(G20) -> 14.957472 | I20: =G20^2 -> 223.72598 | J20: =ABS(G20/C20)*100 -> 14.664189
... A113: 105 | B113: ='Data Mentah'!B110 -> 30/12/2024 | C113: ='Data Mentah'!H110 -> 93 | D113: =$E$4*C113+(1-$E$4)*(D112+E112) -> 93.799639 | E113: =$H$4*(D113-D112)+(1-$H$4)*E112 -> -15.859569 | F113: =D112+E112 -> 100.99639 | G113: =C113-F113 -> -7.9963897 | H113: =ABS(G113) -> 7.9963897 | I113: =G113^2 -> 63.942247 | J113: =ABS(G113/C113)*100 -> 8.5982684
A115: RINGKASAN EVALUASI (Data Uji — 21 Minggu Terakhir)
A116: MAD (Mean Absolute Deviation) | D116: =AVERAGE(H93:H113) -> 5.3232395
A117: MSE (Mean Squared Error) | D117: =AVERAGE(I93:I113) -> 41.920842
A118: MAPE (Mean Absolute Percentage Error) % | D118: =AVERAGE(J93:J113) -> 4.6344085
A119: Kategori (Tabel 2.1) | D119: =IF(D118<10,"Sangat Baik",IF(D118<20,"Baik",IF(D118<=50,"Cukup","Rendah"))) -> Sangat Baik
A120: Prediksi Periode ke-106 | D120: =D113+E113 -> 77.94007
A121: Rata-rata Historis (105 minggu) | D121: =AVERAGE(C9:C113) -> 117.42857

Sheet DES_Nazovel Suppositoria
A1: PERHITUNGAN DOUBLE EXPONENTIAL SMOOTHING — NAZOVEL SUPPOSITORIA
A2: Rumus hidup: Level_t = α·Aktual_t + (1-α)·(Level_(t-1)+Tren_(t-1)); Tren_t = β·(Level_t-Level_(t-1)) + (1-β)·Tren_(t-1); Ramalan_t = Level_(t-1)+Tren_(t-1). Ubah α/β di bawah untuk menguji kombinasi lain — seluruh tabel & ringkasan terhitung ulang otomatis.
A4: Nama Obat: | B4: Nazovel Suppositoria | D4: Alpha (α): | E4: 0.9 | G4: Beta (β): | H4: 0.1
A5: L0 (Level Awal): | B5: ='Data Mentah'!I5 -> 26 | D5: T0 (Tren Awal): | E5: 0
A7: Periode | B7: Minggu | C7: Aktual | D7: Level | E7: Tren | F7: Ramalan | G7: Error | H7: |Error| | I7: Error² | J7: APE (%)
A8: 0 | B8: ='Data Mentah'!B5 -> 26/12/2022 | C8: ='Data Mentah'!I5 -> 26 | D8: =$B$5 -> 26 | E8: =$E$5 -> 0
A9: 1 | B9: ='Data Mentah'!B6 -> 02/01/2023 | C9: ='Data Mentah'!I6 -> 60 | D9: =$E$4*C9+(1-$E$4)*(D8+E8) -> 56.6 | E9: =$H$4*(D9-D8)+(1-$H$4)*E8 -> 3.06 | F9: =D8+E8 -> 26 | G9: =C9-F9 -> 34 | H9: =ABS(G9) -> 34 | I9: =G9^2 -> 1156 | J9: =ABS(G9/C9)*100 -> 56.666667
A10: 2 | B10: ='Data Mentah'!B7 -> 09/01/2023 | C10: ='Data Mentah'!I7 -> 78 | D10: =$E$4*C10+(1-$E$4)*(D9+E9) -> 76.166 | E10: =$H$4*(D10-D9)+(1-$H$4)*E9 -> 4.7106 | F10: =D9+E9 -> 59.66 | G10: =C10-F10 -> 18.34 | H10: =ABS(G10) -> 18.34 | I10: =G10^2 -> 336.3556 | J10: =ABS(G10/C10)*100 -> 23.512821
A11: 3 | B11: ='Data Mentah'!B8 -> 16/01/2023 | C11: ='Data Mentah'!I8 -> 91 | D11: =$E$4*C11+(1-$E$4)*(D10+E10) -> 89.98766 | E11: =$H$4*(D11-D10)+(1-$H$4)*E10 -> 5.621706 | F11: =D10+E10 -> 80.8766 | G11: =C11-F11 -> 10.1234 | H11: =ABS(G11) -> 10.1234 | I11: =G11^2 -> 102.48323 | J11: =ABS(G11/C11)*100 -> 11.124615
A12: 4 | B12: ='Data Mentah'!B9 -> 23/01/2023 | C12: ='Data Mentah'!I9 -> 112 | D12: =$E$4*C12+(1-$E$4)*(D11+E11) -> 110.36094 | E12: =$H$4*(D12-D11)+(1-$H$4)*E11 -> 7.0968631 | F12: =D11+E11 -> 95.609366 | G12: =C12-F12 -> 16.390634 | H12: =ABS(G12) -> 16.390634 | I12: =G12^2 -> 268.65288 | J12: =ABS(G12/C12)*100 -> 14.634495
A13: 5 | B13: ='Data Mentah'!B10 -> 30/01/2023 | C13: ='Data Mentah'!I10 -> 121 | D13: =$E$4*C13+(1-$E$4)*(D12+E12) -> 120.64578 | E13: =$H$4*(D13-D12)+(1-$H$4)*E12 -> 7.4156611 | F13: =D12+E12 -> 117.4578 | G13: =C13-F13 -> 3.5422003 | H13: =ABS(G13) -> 3.5422003 | I13: =G13^2 -> 12.547183 | J13: =ABS(G13/C13)*100 -> 2.9274383
A14: 6 | B14: ='Data Mentah'!B11 -> 06/02/2023 | C14: ='Data Mentah'!I11 -> 121 | D14: =$E$4*C14+(1-$E$4)*(D13+E13) -> 121.70614 | E14: =$H$4*(D14-D13)+(1-$H$4)*E13 -> 6.7801314 | F14: =D13+E13 -> 128.06144 | G14: =C14-F14 -> -7.0614411 | H14: =ABS(G14) -> 7.0614411 | I14: =G14^2 -> 49.86395 | J14: =ABS(G14/C14)*100 -> 5.8359017
A15: 7 | B15: ='Data Mentah'!B12 -> 13/02/2023 | C15: ='Data Mentah'!I12 -> 122 | D15: =$E$4*C15+(1-$E$4)*(D14+E14) -> 122.64863 | E15: =$H$4*(D15-D14)+(1-$H$4)*E14 -> 6.1963666 | F15: =D14+E14 -> 128.48628 | G15: =C15-F15 -> -6.4862755 | H15: =ABS(G15) -> 6.4862755 | I15: =G15^2 -> 42.07177 | J15: =ABS(G15/C15)*100 -> 5.3166193
A16: 8 | B16: ='Data Mentah'!B13 -> 20/02/2023 | C16: ='Data Mentah'!I13 -> 122 | D16: =$E$4*C16+(1-$E$4)*(D15+E15) -> 122.6845 | E16: =$H$4*(D16-D15)+(1-$H$4)*E15 -> 5.5803171 | F16: =D15+E15 -> 128.84499 | G16: =C16-F16 -> -6.8449942 | H16: =ABS(G16) -> 6.8449942 | I16: =G16^2 -> 46.853945 | J16: =ABS(G16/C16)*100 -> 5.6106509
A17: 9 | B17: ='Data Mentah'!B14 -> 27/02/2023 | C17: ='Data Mentah'!I14 -> 123 | D17: =$E$4*C17+(1-$E$4)*(D16+E16) -> 123.52648 | E17: =$H$4*(D17-D16)+(1-$H$4)*E16 -> 5.1064836 | F17: =D16+E16 -> 128.26482 | G17: =C17-F17 -> -5.2648165 | H17: =ABS(G17) -> 5.2648165 | I17: =G17^2 -> 27.718293 | J17: =ABS(G17/C17)*100 -> 4.2803387
A18: 10 | B18: ='Data Mentah'!B15 -> 06/03/2023 | C18: ='Data Mentah'!I15 -> 121 | D18: =$E$4*C18+(1-$E$4)*(D17+E17) -> 121.7633 | E18: =$H$4*(D18-D17)+(1-$H$4)*E17 -> 4.4195168 | F18: =D17+E17 -> 128.63297 | G18: =C18-F18 -> -7.6329653 | H18: =ABS(G18) -> 7.6329653 | I18: =G18^2 -> 58.262159 | J18: =ABS(G18/C18)*100 -> 6.3082358
A19: 11 | B19: ='Data Mentah'!B16 -> 13/03/2023 | C19: ='Data Mentah'!I16 -> 116 | D19: =$E$4*C19+(1-$E$4)*(D18+E18) -> 117.01828 | E19: =$H$4*(D19-D18)+(1-$H$4)*E18 -> 3.5030636 | F19: =D18+E18 -> 126.18281 | G19: =C19-F19 -> -10.182813 | H19: =ABS(G19) -> 10.182813 | I19: =G19^2 -> 103.68969 | J19: =ABS(G19/C19)*100 -> 8.7782873
A20: 12 | B20: ='Data Mentah'!B17 -> 20/03/2023 | C20: ='Data Mentah'!I17 -> 119 | D20: =$E$4*C20+(1-$E$4)*(D19+E19) -> 119.15213 | E20: =$H$4*(D20-D19)+(1-$H$4)*E19 -> 3.3661425 | F20: =D19+E19 -> 120.52134 | G20: =C20-F20 -> -1.5213449 | H20: =ABS(G20) -> 1.5213449 | I20: =G20^2 -> 2.3144903 | J20: =ABS(G20/C20)*100 -> 1.2784411
... A113: 105 | B113: ='Data Mentah'!B110 -> 30/12/2024 | C113: ='Data Mentah'!I110 -> 114 | D113: =$E$4*C113+(1-$E$4)*(D112+E112) -> 116.30454 | E113: =$H$4*(D113-D112)+(1-$H$4)*E112 -> -0.51568827 | F113: =D112+E112 -> 137.04545 | G113: =C113-F113 -> -23.045448 | H113: =ABS(G113) -> 23.045448 | I113: =G113^2 -> 531.09266 | J113: =ABS(G113/C113)*100 -> 20.215305
A115: RINGKASAN EVALUASI (Data Uji — 21 Minggu Terakhir)
A116: MAD (Mean Absolute Deviation) | D116: =AVERAGE(H93:H113) -> 6.6742093
A117: MSE (Mean Squared Error) | D117: =AVERAGE(I93:I113) -> 71.520529
A118: MAPE (Mean Absolute Percentage Error) % | D118: =AVERAGE(J93:J113) -> 5.5075311
A119: Kategori (Tabel 2.1) | D119: =IF(D118<10,"Sangat Baik",IF(D118<20,"Baik",IF(D118<=50,"Cukup","Rendah"))) -> Sangat Baik
A120: Prediksi Periode ke-106 | D120: =D113+E113 -> 115.78886
A121: Rata-rata Historis (105 minggu) | D121: =AVERAGE(C9:C113) -> 118.93333

Sheet DES_Epexol Syrup
A1: PERHITUNGAN DOUBLE EXPONENTIAL SMOOTHING — EPEXOL SYRUP
A2: Rumus hidup: Level_t = α·Aktual_t + (1-α)·(Level_(t-1)+Tren_(t-1)); Tren_t = β·(Level_t-Level_(t-1)) + (1-β)·Tren_(t-1); Ramalan_t = Level_(t-1)+Tren_(t-1). Ubah α/β di bawah untuk menguji kombinasi lain — seluruh tabel & ringkasan terhitung ulang otomatis.
A4: Nama Obat: | B4: Epexol Syrup | D4: Alpha (α): | E4: 0.8 | G4: Beta (β): | H4: 0.1
A5: L0 (Level Awal): | B5: ='Data Mentah'!Q5 -> 13 | D5: T0 (Tren Awal): | E5: 0
A7: Periode | B7: Minggu | C7: Aktual | D7: Level | E7: Tren | F7: Ramalan | G7: Error | H7: |Error| | I7: Error² | J7: APE (%)
A8: 0 | B8: ='Data Mentah'!B5 -> 26/12/2022 | C8: ='Data Mentah'!Q5 -> 13 | D8: =$B$5 -> 13 | E8: =$E$5 -> 0
A9: 1 | B9: ='Data Mentah'!B6 -> 02/01/2023 | C9: ='Data Mentah'!Q6 -> 71 | D9: =$E$4*C9+(1-$E$4)*(D8+E8) -> 59.4 | E9: =$H$4*(D9-D8)+(1-$H$4)*E8 -> 4.64 | F9: =D8+E8 -> 13 | G9: =C9-F9 -> 58 | H9: =ABS(G9) -> 58 | I9: =G9^2 -> 3364 | J9: =ABS(G9/C9)*100 -> 81.690141
A10: 2 | B10: ='Data Mentah'!B7 -> 09/01/2023 | C10: ='Data Mentah'!Q7 -> 88 | D10: =$E$4*C10+(1-$E$4)*(D9+E9) -> 83.208 | E10: =$H$4*(D10-D9)+(1-$H$4)*E9 -> 6.5568 | F10: =D9+E9 -> 64.04 | G10: =C10-F10 -> 23.96 | H10: =ABS(G10) -> 23.96 | I10: =G10^2 -> 574.0816 | J10: =ABS(G10/C10)*100 -> 27.227273
A11: 3 | B11: ='Data Mentah'!B8 -> 16/01/2023 | C11: ='Data Mentah'!Q8 -> 94 | D11: =$E$4*C11+(1-$E$4)*(D10+E10) -> 93.15296 | E11: =$H$4*(D11-D10)+(1-$H$4)*E10 -> 6.895616 | F11: =D10+E10 -> 89.7648 | G11: =C11-F11 -> 4.2352 | H11: =ABS(G11) -> 4.2352 | I11: =G11^2 -> 17.936919 | J11: =ABS(G11/C11)*100 -> 4.5055319
A12: 4 | B12: ='Data Mentah'!B9 -> 23/01/2023 | C12: ='Data Mentah'!Q9 -> 125 | D12: =$E$4*C12+(1-$E$4)*(D11+E11) -> 120.00972 | E12: =$H$4*(D12-D11)+(1-$H$4)*E11 -> 8.8917299 | F12: =D11+E11 -> 100.04858 | G12: =C12-F12 -> 24.951424 | H12: =ABS(G12) -> 24.951424 | I12: =G12^2 -> 622.57356 | J12: =ABS(G12/C12)*100 -> 19.961139
A13: 5 | B13: ='Data Mentah'!B10 -> 30/01/2023 | C13: ='Data Mentah'!Q10 -> 125 | D13: =$E$4*C13+(1-$E$4)*(D12+E12) -> 125.78029 | E13: =$H$4*(D13-D12)+(1-$H$4)*E12 -> 8.5796143 | F13: =D12+E12 -> 128.90145 | G13: =C13-F13 -> -3.9014451 | H13: =ABS(G13) -> 3.9014451 | I13: =G13^2 -> 15.221274 | J13: =ABS(G13/C13)*100 -> 3.1211561
A14: 6 | B14: ='Data Mentah'!B11 -> 06/02/2023 | C14: ='Data Mentah'!Q11 -> 125 | D14: =$E$4*C14+(1-$E$4)*(D13+E13) -> 126.87198 | E14: =$H$4*(D14-D13)+(1-$H$4)*E13 -> 7.830822 | F14: =D13+E13 -> 134.3599 | G14: =C14-F14 -> -9.3599033 | H14: =ABS(G14) -> 9.3599033 | I14: =G14^2 -> 87.60779 | J14: =ABS(G14/C14)*100 -> 7.4879227
A15: 7 | B15: ='Data Mentah'!B12 -> 13/02/2023 | C15: ='Data Mentah'!Q12 -> 119 | D15: =$E$4*C15+(1-$E$4)*(D14+E14) -> 122.14056 | E15: =$H$4*(D15-D14)+(1-$H$4)*E14 -> 6.5745978 | F15: =D14+E14 -> 134.7028 | G15: =C15-F15 -> -15.702803 | H15: =ABS(G15) -> 15.702803 | I15: =G15^2 -> 246.57801 | J15: =ABS(G15/C15)*100 -> 13.195633
A16: 8 | B16: ='Data Mentah'!B13 -> 20/02/2023 | C16: ='Data Mentah'!Q13 -> 118 | D16: =$E$4*C16+(1-$E$4)*(D15+E15) -> 120.14303 | E16: =$H$4*(D16-D15)+(1-$H$4)*E15 -> 5.7173852 | F16: =D15+E15 -> 128.71516 | G16: =C16-F16 -> -10.715158 | H16: =ABS(G16) -> 10.715158 | I16: =G16^2 -> 114.81462 | J16: =ABS(G16/C16)*100 -> 9.0806427
A17: 9 | B17: ='Data Mentah'!B14 -> 27/02/2023 | C17: ='Data Mentah'!Q14 -> 112 | D17: =$E$4*C17+(1-$E$4)*(D16+E16) -> 114.77208 | E17: =$H$4*(D17-D16)+(1-$H$4)*E16 -> 4.6085518 | F17: =D16+E16 -> 125.86042 | G17: =C17-F17 -> -13.860417 | H17: =ABS(G17) -> 13.860417 | I17: =G17^2 -> 192.11115 | J17: =ABS(G17/C17)*100 -> 12.375372
A18: 10 | B18: ='Data Mentah'!B15 -> 06/03/2023 | C18: ='Data Mentah'!Q15 -> 108 | D18: =$E$4*C18+(1-$E$4)*(D17+E17) -> 110.27613 | E18: =$H$4*(D18-D17)+(1-$H$4)*E17 -> 3.698101 | F18: =D17+E17 -> 119.38064 | G18: =C18-F18 -> -11.380635 | H18: =ABS(G18) -> 11.380635 | I18: =G18^2 -> 129.51886 | J18: =ABS(G18/C18)*100 -> 10.537625
A19: 11 | B19: ='Data Mentah'!B16 -> 13/03/2023 | C19: ='Data Mentah'!Q16 -> 112 | D19: =$E$4*C19+(1-$E$4)*(D18+E18) -> 112.39485 | E19: =$H$4*(D19-D18)+(1-$H$4)*E18 -> 3.5401628 | F19: =D18+E18 -> 113.97423 | G19: =C19-F19 -> -1.974228 | H19: =ABS(G19) -> 1.974228 | I19: =G19^2 -> 3.8975763 | J19: =ABS(G19/C19)*100 -> 1.7627036
A20: 12 | B20: ='Data Mentah'!B17 -> 20/03/2023 | C20: ='Data Mentah'!Q17 -> 112 | D20: =$E$4*C20+(1-$E$4)*(D19+E19) -> 112.787 | E20: =$H$4*(D20-D19)+(1-$H$4)*E19 -> 3.2253621 | F20: =D19+E19 -> 115.93501 | G20: =C20-F20 -> -3.9350084 | H20: =ABS(G20) -> 3.9350084 | I20: =G20^2 -> 15.484291 | J20: =ABS(G20/C20)*100 -> 3.5134003
... A113: 105 | B113: ='Data Mentah'!B110 -> 30/12/2024 | C113: ='Data Mentah'!Q110 -> 113 | D113: =$E$4*C113+(1-$E$4)*(D112+E112) -> 119.79809 | E113: =$H$4*(D113-D112)+(1-$H$4)*E112 -> -0.65108671 | F113: =D112+E112 -> 146.99043 | G113: =C113-F113 -> -33.990426 | H113: =ABS(G113) -> 33.990426 | I113: =G113^2 -> 1155.3491 | J113: =ABS(G113/C113)*100 -> 30.080023
A115: RINGKASAN EVALUASI (Data Uji — 21 Minggu Terakhir)
A116: MAD (Mean Absolute Deviation) | D116: =AVERAGE(H93:H113) -> 5.2815634
A117: MSE (Mean Squared Error) | D117: =AVERAGE(I93:I113) -> 77.118358
A118: MAPE (Mean Absolute Percentage Error) % | D118: =AVERAGE(J93:J113) -> 4.3473496
A119: Kategori (Tabel 2.1) | D119: =IF(D118<10,"Sangat Baik",IF(D118<20,"Baik",IF(D118<=50,"Cukup","Rendah"))) -> Sangat Baik
A120: Prediksi Periode ke-106 | D120: =D113+E113 -> 119.147
A121: Rata-rata Historis (105 minggu) | D121: =AVERAGE(C9:C113) -> 122

Sheet DES_Apialys Syrup
A1: PERHITUNGAN DOUBLE EXPONENTIAL SMOOTHING — APIALYS SYRUP
A2: Rumus hidup: Level_t = α·Aktual_t + (1-α)·(Level_(t-1)+Tren_(t-1)); Tren_t = β·(Level_t-Level_(t-1)) + (1-β)·Tren_(t-1); Ramalan_t = Level_(t-1)+Tren_(t-1). Ubah α/β di bawah untuk menguji kombinasi lain — seluruh tabel & ringkasan terhitung ulang otomatis.
A4: Nama Obat: | B4: Apialys Syrup | D4: Alpha (α): | E4: 0.9 | G4: Beta (β): | H4: 0.5
A5: L0 (Level Awal): | B5: ='Data Mentah'!R5 -> 21 | D5: T0 (Tren Awal): | E5: 0
A7: Periode | B7: Minggu | C7: Aktual | D7: Level | E7: Tren | F7: Ramalan | G7: Error | H7: |Error| | I7: Error² | J7: APE (%)
A8: 0 | B8: ='Data Mentah'!B5 -> 26/12/2022 | C8: ='Data Mentah'!R5 -> 21 | D8: =$B$5 -> 21 | E8: =$E$5 -> 0
A9: 1 | B9: ='Data Mentah'!B6 -> 02/01/2023 | C9: ='Data Mentah'!R6 -> 74 | D9: =$E$4*C9+(1-$E$4)*(D8+E8) -> 68.7 | E9: =$H$4*(D9-D8)+(1-$H$4)*E8 -> 23.85 | F9: =D8+E8 -> 21 | G9: =C9-F9 -> 53 | H9: =ABS(G9) -> 53 | I9: =G9^2 -> 2809 | J9: =ABS(G9/C9)*100 -> 71.621622
A10: 2 | B10: ='Data Mentah'!B7 -> 09/01/2023 | C10: ='Data Mentah'!R7 -> 88 | D10: =$E$4*C10+(1-$E$4)*(D9+E9) -> 88.455 | E10: =$H$4*(D10-D9)+(1-$H$4)*E9 -> 21.8025 | F10: =D9+E9 -> 92.55 | G10: =C10-F10 -> -4.55 | H10: =ABS(G10) -> 4.55 | I10: =G10^2 -> 20.7025 | J10: =ABS(G10/C10)*100 -> 5.1704545
A11: 3 | B11: ='Data Mentah'!B8 -> 16/01/2023 | C11: ='Data Mentah'!R8 -> 103 | D11: =$E$4*C11+(1-$E$4)*(D10+E10) -> 103.72575 | E11: =$H$4*(D11-D10)+(1-$H$4)*E10 -> 18.536625 | F11: =D10+E10 -> 110.2575 | G11: =C11-F11 -> -7.2575 | H11: =ABS(G11) -> 7.2575 | I11: =G11^2 -> 52.671306 | J11: =ABS(G11/C11)*100 -> 7.0461165
A12: 4 | B12: ='Data Mentah'!B9 -> 23/01/2023 | C12: ='Data Mentah'!R9 -> 130 | D12: =$E$4*C12+(1-$E$4)*(D11+E11) -> 129.22624 | E12: =$H$4*(D12-D11)+(1-$H$4)*E11 -> 22.018556 | F12: =D11+E11 -> 122.26238 | G12: =C12-F12 -> 7.737625 | H12: =ABS(G12) -> 7.737625 | I12: =G12^2 -> 59.870841 | J12: =ABS(G12/C12)*100 -> 5.9520192
A13: 5 | B13: ='Data Mentah'!B10 -> 30/01/2023 | C13: ='Data Mentah'!R10 -> 118 | D13: =$E$4*C13+(1-$E$4)*(D12+E12) -> 121.32448 | E13: =$H$4*(D13-D12)+(1-$H$4)*E12 -> 7.0583991 | F13: =D12+E12 -> 151.24479 | G13: =C13-F13 -> -33.244794 | H13: =ABS(G13) -> 33.244794 | I13: =G13^2 -> 1105.2163 | J13: =ABS(G13/C13)*100 -> 28.173554
A14: 6 | B14: ='Data Mentah'!B11 -> 06/02/2023 | C14: ='Data Mentah'!R11 -> 117 | D14: =$E$4*C14+(1-$E$4)*(D13+E13) -> 118.13829 | E14: =$H$4*(D14-D13)+(1-$H$4)*E13 -> 1.9361038 | F14: =D13+E13 -> 128.38288 | G14: =C14-F14 -> -11.382878 | H14: =ABS(G14) -> 11.382878 | I14: =G14^2 -> 129.56992 | J14: =ABS(G14/C14)*100 -> 9.7289559
A15: 7 | B15: ='Data Mentah'!B12 -> 13/02/2023 | C15: ='Data Mentah'!R12 -> 113 | D15: =$E$4*C15+(1-$E$4)*(D14+E14) -> 113.70744 | E15: =$H$4*(D15-D14)+(1-$H$4)*E14 -> -1.2473725 | F15: =D14+E14 -> 120.07439 | G15: =C15-F15 -> -7.0743916 | H15: =ABS(G15) -> 7.0743916 | I15: =G15^2 -> 50.047017 | J15: =ABS(G15/C15)*100 -> 6.2605235
A16: 8 | B16: ='Data Mentah'!B13 -> 20/02/2023 | C16: ='Data Mentah'!R13 -> 114 | D16: =$E$4*C16+(1-$E$4)*(D15+E15) -> 113.84601 | E16: =$H$4*(D16-D15)+(1-$H$4)*E15 -> -0.55440247 | F16: =D15+E15 -> 112.46007 | G16: =C16-F16 -> 1.5399333 | H16: =ABS(G16) -> 1.5399333 | I16: =G16^2 -> 2.3713946 | J16: =ABS(G16/C16)*100 -> 1.3508187
A17: 9 | B17: ='Data Mentah'!B14 -> 27/02/2023 | C17: ='Data Mentah'!R14 -> 120 | D17: =$E$4*C17+(1-$E$4)*(D16+E16) -> 119.32916 | E17: =$H$4*(D17-D16)+(1-$H$4)*E16 -> 2.4643756 | F17: =D16+E16 -> 113.2916 | G17: =C17-F17 -> 6.7083958 | H17: =ABS(G17) -> 6.7083958 | I17: =G17^2 -> 45.002574 | J17: =ABS(G17/C17)*100 -> 5.5903298
A18: 10 | B18: ='Data Mentah'!B15 -> 06/03/2023 | C18: ='Data Mentah'!R15 -> 129 | D18: =$E$4*C18+(1-$E$4)*(D17+E17) -> 128.27935 | E18: =$H$4*(D18-D17)+(1-$H$4)*E17 -> 5.7072844 | F18: =D17+E17 -> 121.79354 | G18: =C18-F18 -> 7.2064639 | H18: =ABS(G18) -> 7.2064639 | I18: =G18^2 -> 51.933123 | J18: =ABS(G18/C18)*100 -> 5.5864062
A19: 11 | B19: ='Data Mentah'!B16 -> 13/03/2023 | C19: ='Data Mentah'!R16 -> 122 | D19: =$E$4*C19+(1-$E$4)*(D18+E18) -> 123.19866 | E19: =$H$4*(D19-D18)+(1-$H$4)*E18 -> 0.3132973 | F19: =D18+E18 -> 133.98664 | G19: =C19-F19 -> -11.986638 | H19: =ABS(G19) -> 11.986638 | I19: =G19^2 -> 143.67949 | J19: =ABS(G19/C19)*100 -> 9.8251131
A20: 12 | B20: ='Data Mentah'!B17 -> 20/03/2023 | C20: ='Data Mentah'!R17 -> 123 | D20: =$E$4*C20+(1-$E$4)*(D19+E19) -> 123.0512 | E20: =$H$4*(D20-D19)+(1-$H$4)*E19 -> 0.082914806 | F20: =D19+E19 -> 123.51196 | G20: =C20-F20 -> -0.51196111 | H20: =ABS(G20) -> 0.51196111 | I20: =G20^2 -> 0.26210417 | J20: =ABS(G20/C20)*100 -> 0.41622854
... A113: 105 | B113: ='Data Mentah'!B110 -> 30/12/2024 | C113: ='Data Mentah'!R110 -> 111 | D113: =$E$4*C113+(1-$E$4)*(D112+E112) -> 112.28323 | E113: =$H$4*(D113-D112)+(1-$H$4)*E112 -> -3.1317176 | F113: =D112+E112 -> 123.83234 | G113: =C113-F113 -> -12.83234 | H113: =ABS(G113) -> 12.83234 | I113: =G113^2 -> 164.66894 | J113: =ABS(G113/C113)*100 -> 11.560666
A115: RINGKASAN EVALUASI (Data Uji — 21 Minggu Terakhir)
A116: MAD (Mean Absolute Deviation) | D116: =AVERAGE(H93:H113) -> 6.9110624
A117: MSE (Mean Squared Error) | D117: =AVERAGE(I93:I113) -> 77.597165
A118: MAPE (Mean Absolute Percentage Error) % | D118: =AVERAGE(J93:J113) -> 5.8221684
A119: Kategori (Tabel 2.1) | D119: =IF(D118<10,"Sangat Baik",IF(D118<20,"Baik",IF(D118<=50,"Cukup","Rendah"))) -> Sangat Baik
